Workbook

Sheet 2022_VIE_ENG
A1: Mã tỉnh | B1: Mã tỉnh | C1: Thang điểm/Scale | D1: 1 | E1: 2 | F1: 4 | G1: 6 | H1: 8 | I1: 10 | J1: 11 | K1: 12 | L1: 14 | M1: 15 | N1: 17 | O1: 19 | P1: 20 | Q1: 22 | R1: 24 | S1: 25 | T1: 26 | U1: 27 | V1: 30 | W1: 31 | X1: 33 | Y1: 34 | Z1: 35 | AA1: 36 | AB1: 37 | AC1: 38 | AD1: 40 | AE1: 42 | AF1: 44 | AG1: 45 | AH1: 46 | AI1: 48 | AJ1: 49 | AK1: 51 | AL1: 52 | AM1: 54 | AN1: 56 | AO1: 58 | AP1: 60 | AQ1: 62 | AR1: 64 | AS1: 66 | AT1: 67 | AU1: 68 | AV1: 70 | AW1: 72 | AX1: 74 | AY1: 75 | AZ1: 77 | BA1: 79 | BB1: 80 | BC1: 82 | BD1: 83 | BE1: 84 | BF1: 86 | BG1: 87 | BH1: 89 | BI1: 91 | BJ1: 92 | BK1: 93 | BL1: 94 | BM1: 95 | BN1: 96
A2: Tỉnh/Thành phố trực thuộc trung ương | B2: Tỉnh/Thành phố trực thuộc trung ương | D2: Hà Nội | E2: Hà Giang | F2: Cao Bằng | G2: Bắc Kạn | H2: Tuyên Quang | I2: Lào Cai | J2: Điện Biên | K2: Lai Châu | L2: Sơn La | M2: Yên Bái | N2: Hòa Bình | O2: Thái Nguyên | P2: Lạng Sơn | Q2: Quảng Ninh | R2: Bắc Giang | S2: Phú Thọ | T2: Vĩnh Phúc | U2: Bắc Ninh | V2: Hải Dương | W2: Hải Phòng | X2: Hưng Yên | Y2: Thái Bình | Z2: Hà Nam | AA2: Nam Định | AB2: Ninh Bình | AC2: Thanh Hóa | AD2: Nghệ An | AE2: Hà Tĩnh | AF2: Quảng Bình | AG2: Quảng Trị | AH2: Thừa Thiên-Huế | AI2: Đà Nẵng | AJ2: Quảng Nam | AK2: Quảng Ngãi | AL2: Bình Định | AM2: Phú Yên | AN2: Khánh Hòa | AO2: Ninh Thuận | AP2: Bình Thuận | AQ2: Kon Tum | AR2: Gia Lai | AS2: Đắk Lắk | AT2: Đắk Nông | AU2: Lâm Đồng | AV2: Bình Phước | AW2: Tây Ninh | AX2: Bình Dương | AY2: Đồng Nai | AZ2: Bà Rịa-Vũng Tàu | BA2: TP. Hồ Chí Minh | BB2: Long An | BC2: Tiền Giang | BD2: Bến Tre | BE2: Trà Vinh | BF2: Vĩnh Long | BG2: Đồng Tháp | BH2: An Giang | BI2: Kiên Giang | BJ2: Cần Thơ | BK2: Hậu Giang | BL2: Sóc Trăng | BM2: Bạc Liêu | BN2: Cà Mau
A3: Weighted PAPI Score | B3: Chỉ số PAPI tổng hợp (có trọng số) | C3: 10-80 điểm/points
A4: PAPI 95% CI Low | B4: Chỉ số PAPI tổng hợp (có trọng số) - điểm tối thiểu trong khoảng tin cậy 95%
A5: PAPI 95% CI High | B5: Chỉ số PAPI tổng hợp (có trọng số) - điểm tối đa trong khoảng tin cậy 95%
A6: PAPI Standard Error | B6: Chỉ số PAPI tổng hợp (có trọng số) - sai số
A7: Unweighted PAPI Score | B7: Chỉ số PAPI tổng hợp (không có trọng số) | C7: 10-80 điểm/points | D7: =VLOOKUP(A7,'2022_PAPI_Indicators'!A3:B183,2,FALSE) -> 43.90493 | E7: =VLOOKUP(A7,'2022_PAPI_Indicators'!A3:C183,3,FALSE) -> 41.146988 | F7: 38.803738 | G7: 42.436947 | H7: 43.109154 | I7: 40.397507 | J7: 39.668663 | K7: 42.690647 | L7: 40.869358 | M7: 41.83152 | N7: 41.007774 | O7: 43.016243 | P7: 43.847515 | Q7: 47.876301 | R7: 0 | S7: 44.246758 | T7: 44.308403 | U7: 0 | V7: 42.14352 | W7: 43.603531 | X7: 44.183117 | Y7: 43.514046 | Z7: 42.733124 | AA7: 43.152493 | AB7: 43.164555 | AC7: 46.015366 | AD7: 43.249977 | AE7: 44.313824 | AF7: 42.761436 | AG7: 41.7742 | AH7: 45.384464 | AI7: 42.570354 | AJ7: 42.237701 | AK7: 42.92836 | AL7: 41.660088 | AM7: 40.742329 | AN7: 43.436882 | AO7: 46.000217 | AP7: 44.539753 | AQ7: 39.975605 | AR7: 39.67363 | AS7: 41.122337 | AT7: 40.527431 | AU7: 40.709713 | AV7: 39.934429 | AW7: 39.417038 | AX7: 47.448799 | AY7: 41.263165 | AZ7: 41.992939 | BA7: 41.020382 | BB7: 39.809238 | BC7: 40.976799 | BD7: 40.597153 | BE7: 40.717228 | BF7: 43.024712 | BG7: 42.149784 | BH7: 41.002136 | BI7: 40.040089 | BJ7: 39.974747 | BK7: 42.591606 | BL7: 42.855907 | BM7: 44.911423 | BN7: 41.874588
A8: Unweighted 95% CI Low | B8: Chỉ số PAPI tổng hợp (không có trọng số) - điểm tối thiểu trong khoảng tin cậy 95% | D8: =VLOOKUP(A8,'2022_PAPI_Indicators'!A4:B184,2,FALSE) -> 43.518097 | E8: =VLOOKUP(A8,'2022_PAPI_Indicators'!A3:C183,3,FALSE) -> 40.69569 | F8: =VLOOKUP(A8,'2022_PAPI_Indicators'!A3:D183,4,FALSE) -> 38.151661 | G8: =VLOOKUP(A8,'2022_PAPI_Indicators'!A3:E183,5,FALSE) -> 40.999649 | H8: =VLOOKUP(A8,'2022_PAPI_Indicators'!A3:F183,6,FALSE) -> 42.630917 | I8: =VLOOKUP(A8,'2022_PAPI_Indicators'!A3:G183,7,FALSE) -> 39.353958 | J8: =VLOOKUP(A8,'2022_PAPI_Indicators'!A3:H183,8,FALSE) -> 36.878681 | K8: =VLOOKUP(A8,'2022_PAPI_Indicators'!A3:I183,9,FALSE) -> 42.063129 | L8: =VLOOKUP(A8,'2022_PAPI_Indicators'!A3:J183,10,FALSE) -> 38.007645 | M8: =VLOOKUP(A8,'2022_PAPI_Indicators'!A3:K183,11,FALSE) -> 39.764709 | N8: =VLOOKUP(A8,'2022_PAPI_Indicators'!A3:L183,12,FALSE) -> 39.618702 | O8: =VLOOKUP(A8,'2022_PAPI_Indicators'!A3:M183,13,FALSE) -> 42.748577 | P8: =VLOOKUP(A8,'2022_PAPI_Indicators'!A3:N183,14,FALSE) -> 42.599697 | Q8: =VLOOKUP(A8,'2022_PAPI_Indicators'!A3:O183,15,FALSE) -> 46.555725 | R8: =VLOOKUP(A8,'2022_PAPI_Indicators'!A3:P183,16,FALSE) -> 0 | S8: =VLOOKUP(A8,'2022_PAPI_Indicators'!A3:R183,17,FALSE) -> 43.080505 | T8: =VLOOKUP(A8,'2022_PAPI_Indicators'!A3:S183,18,FALSE) -> 43.282104 | U8: =VLOOKUP(A8,'2022_PAPI_Indicators'!A3:T183,19,FALSE) -> 0 | V8: =VLOOKUP(A8,'2022_PAPI_Indicators'!A3:U183,20,FALSE) -> 41.623455 | W8: =VLOOKUP(A8,'2022_PAPI_Indicators'!A3:V183,21,FALSE) -> 43.264462 | X8: =VLOOKUP(A8,'2022_PAPI_Indicators'!A3:W183,22,FALSE) -> 43.04599 | Y8: =VLOOKUP(A8,'2022_PAPI_Indicators'!A3:X183,23,FALSE) -> 42.72879 | Z8: =VLOOKUP(A8,'2022_PAPI_Indicators'!A3:Y183,24,FALSE) -> 41.536163 | AA8: =VLOOKUP(A8,'2022_PAPI_Indicators'!A3:Z183,25,FALSE) -> 42.756363 | AB8: =VLOOKUP(A8,'2022_PAPI_Indicators'!A3:AA183,26,FALSE) -> 42.757893 | AC8: =VLOOKUP(A8,'2022_PAPI_Indicators'!A3:AB183,27,FALSE) -> 45.726723 | AD8: =VLOOKUP(A8,'2022_PAPI_Indicators'!A3:AC183,28,FALSE) -> 42.832211 | AE8: =VLOOKUP(A8,'2022_PAPI_Indicators'!A3:AD183,29,FALSE) -> 43.135738 | AF8: =VLOOKUP(A8,'2022_PAPI_Indicators'!A3:AE183,30,FALSE) -> 42.095692 | AG8: =VLOOKUP(A8,'2022_PAPI_Indicators'!A3:AF183,31,FALSE) -> 39.958164 | AH8: =VLOOKUP(A8,'2022_PAPI_Indicators'!A3:AG183,32,FALSE) -> 44.921993 | AI8: =VLOOKUP(A8,'2022_PAPI_Indicators'!A3:AH183,33,FALSE) -> 42.100521 | AJ8: =VLOOKUP(A8,'2022_PAPI_Indicators'!A3:AI183,34,FALSE) -> 41.421711 | AK8: =VLOOKUP(A8,'2022_PAPI_Indicators'!A3:AJ183,35,FALSE) -> 42.542549 | AL8: =VLOOKUP(A8,'2022_PAPI_Indicators'!A3:AK183,36,FALSE) -> 40.291451 | AM8: =VLOOKUP(A8,'2022_PAPI_Indicators'!A3:AL183,37,FALSE) -> 39.31916 | AN8: =VLOOKUP(A8,'2022_PAPI_Indicators'!A3:AM183,38,FALSE) -> 42.348782 | AO8: =VLOOKUP(A8,'2022_PAPI_Indicators'!A3:AN183,39,FALSE) -> 42.67308 | AP8: =VLOOKUP(A8,'2022_PAPI_Indicators'!A3:AO183,40,FALSE) -> 41.32695 | AQ8: =VLOOKUP(A8,'2022_PAPI_Indicators'!A3:AP183,41,FALSE) -> 39.081516 | AR8: =VLOOKUP(A8,'2022_PAPI_Indicators'!A3:AQ183,42,FALSE) -> 38.064156 | AS8: =VLOOKUP(A8,'2022_PAPI_Indicators'!A3:AR183,43,FALSE) -> 38.267181 | AT8: =VLOOKUP(A8,'2022_PAPI_Indicators'!A3:AS183,44,FALSE) -> 39.406395 | AU8: =VLOOKUP(A8,'2022_PAPI_Indicators'!A3:AT183,45,FALSE) -> 40.062408 | AV8: =VLOOKUP(A8,'2022_PAPI_Indicators'!A3:AU183,46,FALSE) -> 39.20129 | AW8: =VLOOKUP(A8,'2022_PAPI_Indicators'!A3:AV183,47,FALSE) -> 38.418488 | AX8: =VLOOKUP(A8,'2022_PAPI_Indicators'!A3:AW183,48,FALSE) -> 45.451958 | AY8: =VLOOKUP(A8,'2022_PAPI_Indicators'!A3:AX183,49,FALSE) -> 40.673058 | AZ8: =VLOOKUP(A8,'2022_PAPI_Indicators'!A3:AY183,50,FALSE) -> 40.823223 | BA8: =VLOOKUP(A8,'2022_PAPI_Indicators'!A3:AZ183,51,FALSE) -> 40.478935 | BB8: =VLOOKUP(A8,'2022_PAPI_Indicators'!A3:BA183,52,FALSE) -> 39.311646 | BC8: =VLOOKUP(A8,'2022_PAPI_Indicators'!A3:BB183,53,FALSE) -> 38.709946 | BD8: =VLOOKUP(A8,'2022_PAPI_Indicators'!A3:BC183,54,FALSE) -> 38.188801 | BE8: =VLOOKUP(A8,'2022_PAPI_Indicators'!A3:BD183,55,FALSE) -> 39.409874 | BF8: =VLOOKUP(A8,'2022_PAPI_Indicators'!A3:BE183,56,FALSE) -> 42.217731 | BG8: =VLOOKUP(A8,'2022_PAPI_Indicators'!A3:BF183,57,FALSE) -> 40.934998 | BH8: =VLOOKUP(A8,'2022_PAPI_Indicators'!A3:BG183,58,FALSE) -> 40.546349 | BI8: =VLOOKUP(A8,'2022_PAPI_Indicators'!A3:BH183,59,FALSE) -> 39.395382 | BJ8: =VLOOKUP(A8,'2022_PAPI_Indicators'!A3:BI183,60,FALSE) -> 39.463318 | BK8: =VLOOKUP(A8,'2022_PAPI_Indicators'!A3:BJ183,61,FALSE) -> 41.10535 | BL8: =VLOOKUP(A8,'2022_PAPI_Indicators'!A3:BK183,62,FALSE) -> 42.855907 | BM8: =VLOOKUP(A8,'2022_PAPI_Indicators'!A3:BL183,63,FALSE) -> 44.911423 | BN8: =VLOOKUP(A8,'2022_PAPI_Indicators'!A3:BM183,64,FALSE) -> 41.874588
A9: Unweighted 95% CI High | B9: Chỉ số PAPI tổng hợp (không có trọng số) - điểm tối đa trong khoảng tin cậy 95% | D9: =VLOOKUP(A9,'2022_PAPI_Indicators'!A5:B185,2,FALSE) -> 44.291763 | E9: =VLOOKUP(A9,'2022_PAPI_Indicators'!A4:C184,3,FALSE) -> 41.598286 | F9: =VLOOKUP(A9,'2022_PAPI_Indicators'!A4:D184,4,FALSE) -> 39.455814 | G9: =VLOOKUP(A9,'2022_PAPI_Indicators'!A4:E184,5,FALSE) -> 43.874245 | H9: =VLOOKUP(A9,'2022_PAPI_Indicators'!A4:F184,6,FALSE) -> 43.587391 | I9: =VLOOKUP(A9,'2022_PAPI_Indicators'!A4:G184,7,FALSE) -> 41.441055 | J9: =VLOOKUP(A9,'2022_PAPI_Indicators'!A4:H184,8,FALSE) -> 42.458645 | K9: =VLOOKUP(A9,'2022_PAPI_Indicators'!A4:I184,9,FALSE) -> 43.318165 | L9: =VLOOKUP(A9,'2022_PAPI_Indicators'!A4:J184,10,FALSE) -> 43.731071 | M9: =VLOOKUP(A9,'2022_PAPI_Indicators'!A4:K184,11,FALSE) -> 43.898331 | N9: =VLOOKUP(A9,'2022_PAPI_Indicators'!A4:L184,12,FALSE) -> 42.396847 | O9: =VLOOKUP(A9,'2022_PAPI_Indicators'!A4:M184,13,FALSE) -> 43.283909 | P9: =VLOOKUP(A9,'2022_PAPI_Indicators'!A4:N184,14,FALSE) -> 45.095333 | Q9: =VLOOKUP(A9,'2022_PAPI_Indicators'!A4:O184,15,FALSE) -> 49.196877 | R9: =VLOOKUP(A9,'2022_PAPI_Indicators'!A4:P184,16,FALSE) -> 0 | S9: =VLOOKUP(A9,'2022_PAPI_Indicators'!A4:R184,17,FALSE) -> 45.41301 | T9: =VLOOKUP(A9,'2022_PAPI_Indicators'!A4:S184,18,FALSE) -> 45.334702 | U9: =VLOOKUP(A9,'2022_PAPI_Indicators'!A4:T184,19,FALSE) -> 0 | V9: =VLOOKUP(A9,'2022_PAPI_Indicators'!A4:U184,20,FALSE) -> 42.663586 | W9: =VLOOKUP(A9,'2022_PAPI_Indicators'!A4:V184,21,FALSE) -> 43.9426 | X9: =VLOOKUP(A9,'2022_PAPI_Indicators'!A4:W184,22,FALSE) -> 45.320244 | Y9: =VLOOKUP(A9,'2022_PAPI_Indicators'!A4:X184,23,FALSE) -> 44.299301 | Z9: =VLOOKUP(A9,'2022_PAPI_Indicators'!A4:Y184,24,FALSE) -> 43.930084 | AA9: =VLOOKUP(A9,'2022_PAPI_Indicators'!A4:Z184,25,FALSE) -> 43.548622 | AB9: =VLOOKUP(A9,'2022_PAPI_Indicators'!A4:AA184,26,FALSE) -> 43.571217 | AC9: =VLOOKUP(A9,'2022_PAPI_Indicators'!A4:AB184,27,FALSE) -> 46.304008 | AD9: =VLOOKUP(A9,'2022_PAPI_Indicators'!A4:AC184,28,FALSE) -> 43.667744 | AE9: =VLOOKUP(A9,'2022_PAPI_Indicators'!A4:AD184,29,FALSE) -> 45.491909 | AF9: =VLOOKUP(A9,'2022_PAPI_Indicators'!A4:AE184,30,FALSE) -> 43.427181 | AG9: =VLOOKUP(A9,'2022_PAPI_Indicators'!A4:AF184,31,FALSE) -> 43.590237 | AH9: =VLOOKUP(A9,'2022_PAPI_Indicators'!A4:AG184,32,FALSE) -> 45.846935 | AI9: =VLOOKUP(A9,'2022_PAPI_Indicators'!A4:AH184,33,FALSE) -> 43.040188 | AJ9: =VLOOKUP(A9,'2022_PAPI_Indicators'!A4:AI184,34,FALSE) -> 43.053692 | AK9: =VLOOKUP(A9,'2022_PAPI_Indicators'!A4:AJ184,35,FALSE) -> 43.314171 | AL9: =VLOOKUP(A9,'2022_PAPI_Indicators'!A4:AK184,36,FALSE) -> 43.028725 | AM9: =VLOOKUP(A9,'2022_PAPI_Indicators'!A4:AL184,37,FALSE) -> 42.165497 | AN9: =VLOOKUP(A9,'2022_PAPI_Indicators'!A4:AM184,38,FALSE) -> 44.524982 | AO9: =VLOOKUP(A9,'2022_PAPI_Indicators'!A4:AN184,39,FALSE) -> 49.327354 | AP9: =VLOOKUP(A9,'2022_PAPI_Indicators'!A4:AO184,40,FALSE) -> 47.752556 | AQ9: =VLOOKUP(A9,'2022_PAPI_Indicators'!A4:AP184,41,FALSE) -> 40.869694 | AR9: =VLOOKUP(A9,'2022_PAPI_Indicators'!A4:AQ184,42,FALSE) -> 41.283104 | AS9: =VLOOKUP(A9,'2022_PAPI_Indicators'!A4:AR184,43,FALSE) -> 43.977493 | AT9: =VLOOKUP(A9,'2022_PAPI_Indicators'!A4:AS184,44,FALSE) -> 41.648468 | AU9: =VLOOKUP(A9,'2022_PAPI_Indicators'!A4:AT184,45,FALSE) -> 41.357018 | AV9: =VLOOKUP(A9,'2022_PAPI_Indicators'!A4:AU184,46,FALSE) -> 40.667568 | AW9: =VLOOKUP(A9,'2022_PAPI_Indicators'!A4:AV184,47,FALSE) -> 40.415588 | AX9: =VLOOKUP(A9,'2022_PAPI_Indicators'!A4:AW184,48,FALSE) -> 49.445641 | AY9: =VLOOKUP(A9,'2022_PAPI_Indicators'!A4:AX184,49,FALSE) -> 41.853271 | AZ9: =VLOOKUP(A9,'2022_PAPI_Indicators'!A4:AY184,50,FALSE) -> 43.162655 | BA9: =VLOOKUP(A9,'2022_PAPI_Indicators'!A4:AZ184,51,FALSE) -> 41.561829 | BB9: =VLOOKUP(A9,'2022_PAPI_Indicators'!A4:BA184,52,FALSE) -> 40.306831 | BC9: =VLOOKUP(A9,'2022_PAPI_Indicators'!A4:BB184,53,FALSE) -> 43.243652 | BD9: =VLOOKUP(A9,'2022_PAPI_Indicators'!A4:BC184,54,FALSE) -> 43.005505 | BE9: =VLOOKUP(A9,'2022_PAPI_Indicators'!A4:BD184,55,FALSE) -> 42.024582 | BF9: =VLOOKUP(A9,'2022_PAPI_Indicators'!A4:BE184,56,FALSE) -> 43.831692 | BG9: =VLOOKUP(A9,'2022_PAPI_Indicators'!A4:BF184,57,FALSE) -> 43.364571 | BH9: =VLOOKUP(A9,'2022_PAPI_Indicators'!A4:BG184,58,FALSE) -> 41.457924 | BI9: =VLOOKUP(A9,'2022_PAPI_Indicators'!A4:BH184,59,FALSE) -> 40.684795 | BJ9: =VLOOKUP(A9,'2022_PAPI_Indicators'!A4:BI184,60,FALSE) -> 40.486176 | BK9: =VLOOKUP(A9,'2022_PAPI_Indicators'!A4:BJ184,61,FALSE) -> 44.077862 | BL9: =VLOOKUP(A9,'2022_PAPI_Indicators'!A4:BK184,62,FALSE) -> 42.855907 | BM9: =VLOOKUP(A9,'2022_PAPI_Indicators'!A4:BL184,63,FALSE) -> 44.911423 | BN9: =VLOOKUP(A9,'2022_PAPI_Indicators'!A4:BM184,64,FALSE) -> 41.874588
A10: Unweighted Standard Error | B10: Chỉ số PAPI tổng hợp (không có trọng số) - sai số | D10: =VLOOKUP(A10,'2022_PAPI_Indicators'!A6:B186,2,FALSE) -> 0.23516178 | E10: =VLOOKUP(A10,'2022_PAPI_Indicators'!A5:C185,3,FALSE) -> 0.27435118 | F10: =VLOOKUP(A10,'2022_PAPI_Indicators'!A5:D185,4,FALSE) -> 0.39640722 | G10: =VLOOKUP(A10,'2022_PAPI_Indicators'!A5:E185,5,FALSE) -> 0.87375492 | H10: =VLOOKUP(A10,'2022_PAPI_Indicators'!A5:F185,6,FALSE) -> 0.29072669 | I10: =VLOOKUP(A10,'2022_PAPI_Indicators'!A5:G185,7,FALSE) -> 0.63439029 | J10: =VLOOKUP(A10,'2022_PAPI_Indicators'!A5:H185,8,FALSE) -> 1.6960737 | K10: =VLOOKUP(A10,'2022_PAPI_Indicators'!A5:I185,9,FALSE) -> 0.38147748 | L10: =VLOOKUP(A10,'2022_PAPI_Indicators'!A5:J185,10,FALSE) -> 1.7396802 | M10: =VLOOKUP(A10,'2022_PAPI_Indicators'!A5:K185,11,FALSE) -> 1.2564471 | N10: =VLOOKUP(A10,'2022_PAPI_Indicators'!A5:L185,12,FALSE) -> 0.84443939 | O10: =VLOOKUP(A10,'2022_PAPI_Indicators'!A5:M185,13,FALSE) -> 0.16271915 | P10: =VLOOKUP(A10,'2022_PAPI_Indicators'!A5:N185,14,FALSE) -> 0.75856733 | Q10: =VLOOKUP(A10,'2022_PAPI_Indicators'!A5:O185,15,FALSE) -> 0.80279803 | R10: =VLOOKUP(A10,'2022_PAPI_Indicators'!A5:P185,16,FALSE) -> 0 | S10: =VLOOKUP(A10,'2022_PAPI_Indicators'!A5:R185,17,FALSE) -> 0.70898169 | T10: =VLOOKUP(A10,'2022_PAPI_Indicators'!A5:S185,18,FALSE) -> 0.62390369 | U10: =VLOOKUP(A10,'2022_PAPI_Indicators'!A5:T185,19,FALSE) -> 0 | V10: =VLOOKUP(A10,'2022_PAPI_Indicators'!A5:U185,20,FALSE) -> 0.3161568 | W10: =VLOOKUP(A10,'2022_PAPI_Indicators'!A5:V185,21,FALSE) -> 0.20612636 | X10: =VLOOKUP(A10,'2022_PAPI_Indicators'!A5:W185,22,FALSE) -> 0.6912778 | Y10: =VLOOKUP(A10,'2022_PAPI_Indicators'!A5:X185,23,FALSE) -> 0.47736824 | Z10: =VLOOKUP(A10,'2022_PAPI_Indicators'!A5:Y185,24,FALSE) -> 0.7276504 | AA10: =VLOOKUP(A10,'2022_PAPI_Indicators'!A5:Z185,25,FALSE) -> 0.24081306 | AB10: =VLOOKUP(A10,'2022_PAPI_Indicators'!A5:AA185,26,FALSE) -> 0.24721676 | AC10: =VLOOKUP(A10,'2022_PAPI_Indicators'!A5:AB185,27,FALSE) -> 0.1754698 | AD10: =VLOOKUP(A10,'2022_PAPI_Indicators'!A5:AC185,28,FALSE) -> 0.25396627 | AE10: =VLOOKUP(A10,'2022_PAPI_Indicators'!A5:AD185,29,FALSE) -> 0.71617573 | AF10: =VLOOKUP(A10,'2022_PAPI_Indicators'!A5:AE185,30,FALSE) -> 0.40471655 | AG10: =VLOOKUP(A10,'2022_PAPI_Indicators'!A5:AF185,31,FALSE) -> 1.1039977 | AH10: =VLOOKUP(A10,'2022_PAPI_Indicators'!A5:AG185,32,FALSE) -> 0.28114432 | AI10: =VLOOKUP(A10,'2022_PAPI_Indicators'!A5:AH185,33,FALSE) -> 0.28562003 | AJ10: =VLOOKUP(A10,'2022_PAPI_Indicators'!A5:AI185,34,FALSE) -> 0.4960534 | AK10: =VLOOKUP(A10,'2022_PAPI_Indicators'!A5:AJ185,35,FALSE) -> 0.23454149 | AL10: =VLOOKUP(A10,'2022_PAPI_Indicators'!A5:AK185,36,FALSE) -> 0.83201498 | AM10: =VLOOKUP(A10,'2022_PAPI_Indicators'!A5:AL185,37,FALSE) -> 0.86516559 | AN10: =VLOOKUP(A10,'2022_PAPI_Indicators'!A5:AM185,38,FALSE) -> 0.66147268 | AO10: =VLOOKUP(A10,'2022_PAPI_Indicators'!A5:AN185,39,FALSE) -> 2.0226173 | AP10: =VLOOKUP(A10,'2022_PAPI_Indicators'!A5:AO185,40,FALSE) -> 1.953112 | AQ10: =VLOOKUP(A10,'2022_PAPI_Indicators'!A5:AP185,41,FALSE) -> 0.54353112 | AR10: =VLOOKUP(A10,'2022_PAPI_Indicators'!A5:AQ185,42,FALSE) -> 0.97842455 | AS10: =VLOOKUP(A10,'2022_PAPI_Indicators'!A5:AR185,43,FALSE) -> 1.7356935 | AT10: =VLOOKUP(A10,'2022_PAPI_Indicators'!A5:AS185,44,FALSE) -> 0.68149513 | AU10: =VLOOKUP(A10,'2022_PAPI_Indicators'!A5:AT185,45,FALSE) -> 0.39350551 | AV10: =VLOOKUP(A10,'2022_PAPI_Indicators'!A5:AU185,46,FALSE) -> 0.44568712 | AW10: =VLOOKUP(A10,'2022_PAPI_Indicators'!A5:AV185,47,FALSE) -> 0.60703444 | AX10: =VLOOKUP(A10,'2022_PAPI_Indicators'!A5:AW185,48,FALSE) -> 1.213912 | AY10: =VLOOKUP(A10,'2022_PAPI_Indicators'!A5:AX185,49,FALSE) -> 0.3587358 | AZ10: =VLOOKUP(A10,'2022_PAPI_Indicators'!A5:AY185,50,FALSE) -> 0.71108896 | BA10: =VLOOKUP(A10,'2022_PAPI_Indicators'!A5:AZ185,51,FALSE) -> 0.32915464 | BB10: =VLOOKUP(A10,'2022_PAPI_Indicators'!A5:BA185,52,FALSE) -> 0.30249527 | BC10: =VLOOKUP(A10,'2022_PAPI_Indicators'!A5:BB185,53,FALSE) -> 1.3780559 | BD10: =VLOOKUP(A10,'2022_PAPI_Indicators'!A5:BC185,54,FALSE) -> 1.4640754 | BE10: =VLOOKUP(A10,'2022_PAPI_Indicators'!A5:BD185,55,FALSE) -> 0.79476118 | BF10: =VLOOKUP(A10,'2022_PAPI_Indicators'!A5:BE185,56,FALSE) -> 0.4905751 | BG10: =VLOOKUP(A10,'2022_PAPI_Indicators'!A5:BF185,57,FALSE) -> 0.73848695 | BH10: =VLOOKUP(A10,'2022_PAPI_Indicators'!A5:BG185,58,FALSE) -> 0.27707952 | BI10: =VLOOKUP(A10,'2022_PAPI_Indicators'!A5:BH185,59,FALSE) -> 0.39192814 | BJ10: =VLOOKUP(A10,'2022_PAPI_Indicators'!A5:BI185,60,FALSE) -> 0.31090513 | BK10: =VLOOKUP(A10,'2022_PAPI_Indicators'!A5:BJ185,61,FALSE) -> 0.90351772 | BL10: =VLOOKUP(A10,'2022_PAPI_Indicators'!A5:BK185,62,FALSE) -> 0 | BM10: =VLOOKUP(A10,'2022_PAPI_Indicators'!A5:BL185,63,FALSE) -> 0 | BN10: =VLOOKUP(A10,'2022_PAPI_Indicators'!A5:BM185,64,FALSE) -> 0
A11: Dimension 1: Participation | B11: Chỉ số nội dung 1: Tham gia của người dân ở cấp cơ sở | C11: 1-10 điểm/points | D11: =VLOOKUP(A11,'2022_PAPI_Indicators'!A6:B186,2,) -> 5.8254476 | E11: =VLOOKUP(A11,'2022_PAPI_Indicators'!A6:C186,3,FALSE) -> 4.9973364 | F11: =VLOOKUP(A11,'2022_PAPI_Indicators'!A6:D186,4,FALSE) -> 4.4906936 | G11: =VLOOKUP(A11,'2022_PAPI_Indicators'!A6:E186,5,FALSE) -> 5.3885055 | H11: =VLOOKUP(A11,'2022_PAPI_Indicators'!A6:F186,6,FALSE) -> 5.2460127 | I11: =VLOOKUP(A11,'2022_PAPI_Indicators'!A6:G186,7,FALSE) -> 5.0275598 | J11: =VLOOKUP(A11,'2022_PAPI_Indicators'!A6:H186,8,FALSE) -> 4.438293 | K11: =VLOOKUP(A11,'2022_PAPI_Indicators'!A6:I186,9,FALSE) -> 5.5805297 | L11: =VLOOKUP(A11,'2022_PAPI_Indicators'!A6:J186,10,FALSE) -> 4.7769065 | M11: =VLOOKUP(A11,'2022_PAPI_Indicators'!A6:K186,11,FALSE) -> 4.9544053 | N11: =VLOOKUP(A11,'2022_PAPI_Indicators'!A6:L186,12,FALSE) -> 5.0889664 | O11: =VLOOKUP(A11,'2022_PAPI_Indicators'!A6:M186,13,FALSE) -> 5.3816071 | P11: =VLOOKUP(A11,'2022_PAPI_Indicators'!A6:N186,14,FALSE) -> 5.8164401 | Q11: =VLOOKUP(A11,'2022_PAPI_Indicators'!A6:O186,15,FALSE) -> 5.7475762 | R11: =VLOOKUP(A11,'2022_PAPI_Indicators'!A6:P186,16,FALSE) -> 0 | S11: =VLOOKUP(A11,'2022_PAPI_Indicators'!A6:R186,17,FALSE) -> 5.7516823 | T11: =VLOOKUP(A11,'2022_PAPI_Indicators'!A6:S186,18,FALSE) -> 5.4361572 | U11: =VLOOKUP(A11,'2022_PAPI_Indicators'!A6:T186,19,FALSE) -> 5.8174157 | V11: =VLOOKUP(A11,'2022_PAPI_Indicators'!A6:U186,20,FALSE) -> 5.334476 | W11: =VLOOKUP(A11,'2022_PAPI_Indicators'!A6:V186,21,FALSE) -> 5.3938642 | X11: =VLOOKUP(A11,'2022_PAPI_Indicators'!A6:W186,22,FALSE) -> 5.4940963 | Y11: =VLOOKUP(A11,'2022_PAPI_Indicators'!A6:X186,23,FALSE) -> 5.3871198 | Z11: =VLOOKUP(A11,'2022_PAPI_Indicators'!A6:Y186,24,FALSE) -> 5.0631166 | AA11: =VLOOKUP(A11,'2022_PAPI_Indicators'!A6:Z186,25,FALSE) -> 5.6298561 | AB11: =VLOOKUP(A11,'2022_PAPI_Indicators'!A6:AA186,26,FALSE) -> 5.2587337 | AC11: =VLOOKUP(A11,'2022_PAPI_Indicators'!A6:AB186,27,FALSE) -> 6.1073642 | AD11: =VLOOKUP(A11,'2022_PAPI_Indicators'!A6:AC186,28,FALSE) -> 5.6093493 | AE11: =VLOOKUP(A11,'2022_PAPI_Indicators'!A6:AD186,29,FALSE) -> 5.3757567 | AF11: =VLOOKUP(A11,'2022_PAPI_Indicators'!A6:AE186,30,FALSE) -> 4.9196992 | AG11: =VLOOKUP(A11,'2022_PAPI_Indicators'!A6:AF186,31,FALSE) -> 4.9741263 | AH11: =VLOOKUP(A11,'2022_PAPI_Indicators'!A6:AG186,32,FALSE) -> 5.7721181 | AI11: =VLOOKUP(A11,'2022_PAPI_Indicators'!A6:AH186,33,FALSE) -> 4.4935174 | AJ11: =VLOOKUP(A11,'2022_PAPI_Indicators'!A6:AI186,34,FALSE) -> 4.7812653 | AK11: =VLOOKUP(A11,'2022_PAPI_Indicators'!A6:AJ186,35,FALSE) -> 5.0435991 | AL11: =VLOOKUP(A11,'2022_PAPI_Indicators'!A6:AK186,36,FALSE) -> 4.3365436 | AM11: =VLOOKUP(A11,'2022_PAPI_Indicators'!A6:AL186,37,FALSE) -> 4.3876119 | AN11: =VLOOKUP(A11,'2022_PAPI_Indicators'!A6:AM186,38,FALSE) -> 4.4982848 | AO11: =VLOOKUP(A11,'2022_PAPI_Indicators'!A6:AN186,39,FALSE) -> 5.4048333 | AP11: =VLOOKUP(A11,'2022_PAPI_Indicators'!A6:AO186,40,FALSE) -> 5.4278936 | AQ11: =VLOOKUP(A11,'2022_PAPI_Indicators'!A6:AP186,41,FALSE) -> 4.7477837 | AR11: =VLOOKUP(A11,'2022_PAPI_Indicators'!A6:AQ186,42,FALSE) -> 5.0252843 | AS11: =VLOOKUP(A11,'2022_PAPI_Indicators'!A6:AR186,43,FALSE) -> 5.1387873 | AT11: =VLOOKUP(A11,'2022_PAPI_Indicators'!A6:AS186,44,FALSE) -> 4.7923436 | AU11: =VLOOKUP(A11,'2022_PAPI_Indicators'!A6:AT186,45,FALSE) -> 5.0606523 | AV11: =VLOOKUP(A11,'2022_PAPI_Indicators'!A6:AU186,46,FALSE) -> 5.0272536 | AW11: =VLOOKUP(A11,'2022_PAPI_Indicators'!A6:AV186,47,FALSE) -> 4.2720084 | AX11: =VLOOKUP(A11,'2022_PAPI_Indicators'!A6:AW186,48,FALSE) -> 5.9493718 | AY11: =VLOOKUP(A11,'2022_PAPI_Indicators'!A6:AX186,49,FALSE) -> 4.7767591 | AZ11: =VLOOKUP(A11,'2022_PAPI_Indicators'!A6:AY186,50,FALSE) -> 4.3234725 | BA11: =VLOOKUP(A11,'2022_PAPI_Indicators'!A6:AZ186,51,FALSE) -> 4.5682454 | BB11: =VLOOKUP(A11,'2022_PAPI_Indicators'!A6:BA186,52,FALSE) -> 4.8123226 | BC11: =VLOOKUP(A11,'2022_PAPI_Indicators'!A6:BB186,53,FALSE) -> 4.063168 | BD11: =VLOOKUP(A11,'2022_PAPI_Indicators'!A6:BC186,54,FALSE) -> 4.2259784 | BE11: =VLOOKUP(A11,'2022_PAPI_Indicators'!A6:BD186,55,FALSE) -> 4.1161256 | BF11: =VLOOKUP(A11,'2022_PAPI_Indicators'!A6:BE186,56,FALSE) -> 4.5832973 | BG11: =VLOOKUP(A11,'2022_PAPI_Indicators'!A6:BF186,57,FALSE) -> 4.3295116 | BH11: =VLOOKUP(A11,'2022_PAPI_Indicators'!A6:BG186,58,FALSE) -> 4.4517913 | BI11: =VLOOKUP(A11,'2022_PAPI_Indicators'!A6:BH186,59,FALSE) -> 3.7754788 | BJ11: =VLOOKUP(A11,'2022_PAPI_Indicators'!A6:BI186,60,FALSE) -> 3.711127 | BK11: =VLOOKUP(A11,'2022_PAPI_Indicators'!A6:BJ186,61,FALSE) -> 4.2705483 | BL11: =VLOOKUP(A11,'2022_PAPI_Indicators'!A6:BK186,62,FALSE) -> 4.492063 | BM11: =VLOOKUP(A11,'2022_PAPI_Indicators'!A6:BL186,63,FALSE) -> 5.0389547 | BN11: =VLOOKUP(A11,'2022_PAPI_Indicators'!A6:BM186,64,FALSE) -> 4.177804
A12: Civic Knowledge | B12: 1.1: Tri thức công dân | C12: 0.25-2.5 điểm | D12: =VLOOKUP(A12,'2022_PAPI_Indicators'!A7:B187,2,) -> 1.2902536 | E12: =VLOOKUP(A12,'2022_PAPI_Indicators'!A7:C187,3,FALSE) -> 0.8524285 | F12: =VLOOKUP(A12,'2022_PAPI_Indicators'!A7:D187,4,FALSE) -> 0.85104495 | G12: =VLOOKUP(A12,'2022_PAPI_Indicators'!A7:E187,5,FALSE) -> 1.0590185 | H12: =VLOOKUP(A12,'2022_PAPI_Indicators'!A7:F187,6,FALSE) -> 0.92048329 | I12: =VLOOKUP(A12,'2022_PAPI_Indicators'!A7:G187,7,FALSE) -> 0.92007864 | J12: =VLOOKUP(A12,'2022_PAPI_Indicators'!A7:H187,8,FALSE) -> 0.67026371 | K12: =VLOOKUP(A12,'2022_PAPI_Indicators'!A7:I187,9,FALSE) -> 1.1388193 | L12: =VLOOKUP(A12,'2022_PAPI_Indicators'!A7:J187,10,FALSE) -> 0.8984074 | M12: =VLOOKUP(A12,'2022_PAPI_Indicators'!A7:K187,11,FALSE) -> 0.93147165 | N12: =VLOOKUP(A12,'2022_PAPI_Indicators'!A7:L187,12,FALSE) -> 0.88282299 | O12: =VLOOKUP(A12,'2022_PAPI_Indicators'!A7:M187,13,FALSE) -> 1.1097713 | P12: =VLOOKUP(A12,'2022_PAPI_Indicators'!A7:N187,14,FALSE) -> 1.0883383 | Q12: =VLOOKUP(A12,'2022_PAPI_Indicators'!A7:O187,15,FALSE) -> 1.3968127 | R12: =VLOOKUP(A12,'2022_PAPI_Indicators'!A7:P187,16,FALSE) -> 0 | S12: =VLOOKUP(A12,'2022_PAPI_Indicators'!A7:R187,17,FALSE) -> 1.1729802 | T12: =VLOOKUP(A12,'2022_PAPI_Indicators'!A7:S187,18,FALSE) -> 1.1823511 | U12: =VLOOKUP(A12,'2022_PAPI_Indicators'!A7:T187,19,FALSE) -> 1.3509467 | V12: =VLOOKUP(A12,'2022_PAPI_Indicators'!A7:U187,20,FALSE) -> 1.0244768 | W12: =VLOOKUP(A12,'2022_PAPI_Indicators'!A7:V187,21,FALSE) -> 0.9929195 | X12: =VLOOKUP(A12,'2022_PAPI_Indicators'!A7:W187,22,FALSE) -> 1.126838 | Y12: =VLOOKUP(A12,'2022_PAPI_Indicators'!A7:X187,23,FALSE) -> 1.1201975 | Z12: =VLOOKUP(A12,'2022_PAPI_Indicators'!A7:Y187,24,FALSE) -> 0.99119818 | AA12: =VLOOKUP(A12,'2022_PAPI_Indicators'!A7:Z187,25,FALSE) -> 1.0403043 | AB12: =VLOOKUP(A12,'2022_PAPI_Indicators'!A7:AA187,26,FALSE) -> 1.0206527 | AC12: =VLOOKUP(A12,'2022_PAPI_Indicators'!A7:AB187,27,FALSE) -> 1.2935107 | AD12: =VLOOKUP(A12,'2022_PAPI_Indicators'!A7:AC187,28,FALSE) -> 1.1703758 | AE12: =VLOOKUP(A12,'2022_PAPI_Indicators'!A7:AD187,29,FALSE) -> 1.0169487 | AF12: =VLOOKUP(A12,'2022_PAPI_Indicators'!A7:AE187,30,FALSE) -> 0.9764145 | AG12: =VLOOKUP(A12,'2022_PAPI_Indicators'!A7:AF187,31,FALSE) -> 0.93942249 | AH12: =VLOOKUP(A12,'2022_PAPI_Indicators'!A7:AG187,32,FALSE) -> 1.1248075 | AI12: =VLOOKUP(A12,'2022_PAPI_Indicators'!A7:AH187,33,FALSE) -> 1.1115048 | AJ12: =VLOOKUP(A12,'2022_PAPI_Indicators'!A7:AI187,34,FALSE) -> 1.112101 | AK12: =VLOOKUP(A12,'2022_PAPI_Indicators'!A7:AJ187,35,FALSE) -> 1.1002645 | AL12: =VLOOKUP(A12,'2022_PAPI_Indicators'!A7:AK187,36,FALSE) -> 0.88206303 | AM12: =VLOOKUP(A12,'2022_PAPI_Indicators'!A7:AL187,37,FALSE) -> 0.87195921 | AN12: =VLOOKUP(A12,'2022_PAPI_Indicators'!A7:AM187,38,FALSE) -> 1.0463156 | AO12: =VLOOKUP(A12,'2022_PAPI_Indicators'!A7:AN187,39,FALSE) -> 1.2066787 | AP12: =VLOOKUP(A12,'2022_PAPI_Indicators'!A7:AO187,40,FALSE) -> 0.9538914 | AQ12: =VLOOKUP(A12,'2022_PAPI_Indicators'!A7:AP187,41,FALSE) -> 0.83089882 | AR12: =VLOOKUP(A12,'2022_PAPI_Indicators'!A7:AQ187,42,FALSE) -> 0.90518898 | AS12: =VLOOKUP(A12,'2022_PAPI_Indicators'!A7:AR187,43,FALSE) -> 0.99547279 | AT12: =VLOOKUP(A12,'2022_PAPI_Indicators'!A7:AS187,44,FALSE) -> 0.96308303 | AU12: =VLOOKUP(A12,'2022_PAPI_Indicators'!A7:AT187,45,FALSE) -> 1.0140576 | AV12: =VLOOKUP(A12,'2022_PAPI_Indicators'!A7:AU187,46,FALSE) -> 1.0476226 | AW12: =VLOOKUP(A12,'2022_PAPI_Indicators'!A7:AV187,47,FALSE) -> 0.85741973 | AX12: =VLOOKUP(A12,'2022_PAPI_Indicators'!A7:AW187,48,FALSE) -> 1.2565695 | AY12: =VLOOKUP(A12,'2022_PAPI_Indicators'!A7:AX187,49,FALSE) -> 1.0599449 | AZ12: =VLOOKUP(A12,'2022_PAPI_Indicators'!A7:AY187,50,FALSE) -> 1.1245034 | BA12: =VLOOKUP(A12,'2022_PAPI_Indicators'!A7:AZ187,51,FALSE) -> 0.92631185 | BB12: =VLOOKUP(A12,'2022_PAPI_Indicators'!A7:BA187,52,FALSE) -> 0.9038102 | BC12: =VLOOKUP(A12,'2022_PAPI_Indicators'!A7:BB187,53,FALSE) -> 0.84060413 | BD12: =VLOOKUP(A12,'2022_PAPI_Indicators'!A7:BC187,54,FALSE) -> 0.7469399 | BE12: =VLOOKUP(A12,'2022_PAPI_Indicators'!A7:BD187,55,FALSE) -> 0.86559451 | BF12: =VLOOKUP(A12,'2022_PAPI_Indicators'!A7:BE187,56,FALSE) -> 1.0388256 | BG12: =VLOOKUP(A12,'2022_PAPI_Indicators'!A7:BF187,57,FALSE) -> 0.79635429 | BH12: =VLOOKUP(A12,'2022_PAPI_Indicators'!A7:BG187,58,FALSE) -> 0.75430393 | BI12: =VLOOKUP(A12,'2022_PAPI_Indicators'!A7:BH187,59,FALSE) -> 0.76570642 | BJ12: =VLOOKUP(A12,'2022_PAPI_Indicators'!A7:BI187,60,FALSE) -> 0.70996755 | BK12: =VLOOKUP(A12,'2022_PAPI_Indicators'!A7:BJ187,61,FALSE) -> 0.93277735 | BL12: =VLOOKUP(A12,'2022_PAPI_Indicators'!A7:BK187,62,FALSE) -> 0.88113147 | BM12: =VLOOKUP(A12,'2022_PAPI_Indicators'!A7:BL187,63,FALSE) -> 1.1367943 | BN12: =VLOOKUP(A12,'2022_PAPI_Indicators'!A7:BM187,64,FALSE) -> 0.98122859
A13: Proportion with Civic Knowledge | B13: Hiểu biết về chính sách hiện hành (%) | C13: 0%-100% | D13: =VLOOKUP(A13,'2022_PAPI_Indicators'!A8:B188,2, FALSE) -> 0.67658985 | E13: 0.43581903 | F13: 0.44629556 | G13: 0.57596636 | H13: 0.46699661 | I13: 0.48171157 | J13: 0.31916142 | K13: 0.52844673 | L13: 0.46629402 | M13: 0.50095612 | N13: 0.46893588 | O13: 0.54792607 | P13: 0.53961515 | Q13: 0.69288844 | R13: =VLOOKUP(A13,'2022_PAPI_Indicators'!A8:P188,16,FALSE) -> 0 | S13: 0.53720683 | T13: 0.57189351 | U13: 0.81537098 | V13: 0.46294346 | W13: 0.41227141 | X13: 0.55237967 | Y13: 0.4691762 | Z13: 0.44025752 | AA13: 0.52450961 | AB13: 0.38741013 | AC13: 0.63067544 | AD13: 0.66341233 | AE13: 0.52679646 | AF13: 0.54764712 | AG13: 0.55660522 | AH13: 0.62320167 | AI13: 0.61847615 | AJ13: 0.57207859 | AK13: 0.60019684 | AL13: 0.42103681 | AM13: 0.39798355 | AN13: 0.6487866 | AO13: 0.69148958 | AP13: 0.63496542 | AQ13: 0.4686417 | AR13: 0.50565881 | AS13: 0.48533183 | AT13: 0.55154967 | AU13: 0.64805692 | AV13: 0.39637375 | AW13: 0.38860178 | AX13: 0.80665302 | AY13: 0.562859 | AZ13: 0.60105675 | BA13: 0.49248683 | BB13: 0.45162779 | BC13: 0.39247626 | BD13: 0.30962282 | BE13: 0.38950348 | BF13: 0.56799775 | BG13: 0.39571807 | BH13: 0.34405887 | BI13: 0.34905931 | BJ13: 0.37604687 | BK13: 0.461418 | BL13: 0.39220703 | BM13: 0.60810333 | BN13: 0.51529181
A14: Knowledge of Leaders | B14: Hiểu biết về vị trí lãnh đạo (%) | C14: 0%-100% | D14: =VLOOKUP(A14,'2022_PAPI_Indicators'!A9:B189,2, FALSE) -> 0.586375 | E14: =VLOOKUP(A14,'2022_PAPI_Indicators'!A9:C189,3,FALSE) -> 0.31758249 | F14: =VLOOKUP(A14,'2022_PAPI_Indicators'!A9:D189,4,FALSE) -> 0.3111144 | G14: =VLOOKUP(A14,'2022_PAPI_Indicators'!A9:E189,5,FALSE) -> 0.43114442 | H14: =VLOOKUP(A14,'2022_PAPI_Indicators'!A9:F189,6,FALSE) -> 0.36248684 | I14: =VLOOKUP(A14,'2022_PAPI_Indicators'!A9:G189,7,FALSE) -> 0.35476965 | J14: =VLOOKUP(A14,'2022_PAPI_Indicators'!A9:H189,8,FALSE) -> 0.21398705 | K14: =VLOOKUP(A14,'2022_PAPI_Indicators'!A9:I189,9,FALSE) -> 0.52583826 | L14: =VLOOKUP(A14,'2022_PAPI_Indicators'!A9:J189,10,FALSE) -> 0.34321511 | M14: =VLOOKUP(A14,'2022_PAPI_Indicators'!A9:K189,11,FALSE) -> 0.35527453 | N14: =VLOOKUP(A14,'2022_PAPI_Indicators'!A9:L189,12,FALSE) -> 0.32804137 | O14: =VLOOKUP(A14,'2022_PAPI_Indicators'!A9:M189,13,FALSE) -> 0.49027807 | P14: =VLOOKUP(A14,'2022_PAPI_Indicators'!A9:N189,14,FALSE) -> 0.475382 | Q14: =VLOOKUP(A14,'2022_PAPI_Indicators'!A9:O189,15,FALSE) -> 0.67294484 | R14: =VLOOKUP(A14,'2022_PAPI_Indicators'!A9:P189,16,FALSE) -> 0 | S14: =VLOOKUP(A14,'2022_PAPI_Indicators'!A9:R189,17,FALSE) -> 0.55182344 | T14: =VLOOKUP(A14,'2022_PAPI_Indicators'!A9:S189,18,FALSE) -> 0.54280978 | U14: =VLOOKUP(A14,'2022_PAPI_Indicators'!A9:T189,19,FALSE) -> 0.57093376 | V14: =VLOOKUP(A14,'2022_PAPI_Indicators'!A9:U189,20,FALSE) -> 0.4569521 | W14: =VLOOKUP(A14,'2022_PAPI_Indicators'!A9:V189,21,FALSE) -> 0.45423722 | X14: =VLOOKUP(A14,'2022_PAPI_Indicators'!A9:W189,22,FALSE) -> 0.50322169 | Y14: =VLOOKUP(A14,'2022_PAPI_Indicators'!A9:X189,23,FALSE) -> 0.53892082 | Z14: =VLOOKUP(A14,'2022_PAPI_Indicators'!A9:Y189,24,FALSE) -> 0.43871406 | AA14: =VLOOKUP(A14,'2022_PAPI_Indicators'!A9:Z189,25,FALSE) -> 0.44023794 | AB14: =VLOOKUP(A14,'2022_PAPI_Indicators'!A9:AA189,26,FALSE) -> 0.49131957 | AC14: =VLOOKUP(A14,'2022_PAPI_Indicators'!A9:AB189,27,FALSE) -> 0.61222732 | AD14: =VLOOKUP(A14,'2022_PAPI_Indicators'!A9:AC189,28,FALSE) -> 0.48640567 | AE14: =VLOOKUP(A14,'2022_PAPI_Indicators'!A9:AD189,29,FALSE) -> 0.41833395 | AF14: =VLOOKUP(A14,'2022_PAPI_Indicators'!A9:AE189,30,FALSE) -> 0.37187824 | AG14: =VLOOKUP(A14,'2022_PAPI_Indicators'!A9:AF189,31,FALSE) -> 0.33451739 | AH14: =VLOOKUP(A14,'2022_PAPI_Indicators'!A9:AG189,32,FALSE) -> 0.46600586 | AI14: =VLOOKUP(A14,'2022_PAPI_Indicators'!A9:AH189,33,FALSE) -> 0.45654395 | AJ14: =VLOOKUP(A14,'2022_PAPI_Indicators'!A9:AI189,34,FALSE) -> 0.48027265 | AK14: =VLOOKUP(A14,'2022_PAPI_Indicators'!A9:AJ189,35,FALSE) -> 0.45569226 | AL14: =VLOOKUP(A14,'2022_PAPI_Indicators'!A9:AK189,36,FALSE) -> 0.35131538 | AM14: =VLOOKUP(A14,'2022_PAPI_Indicators'!A9:AL189,37,FALSE) -> 0.35386086 | AN14: =VLOOKUP(A14,'2022_PAPI_Indicators'!A9:AM189,38,FALSE) -> 0.38344273 | AO14: =VLOOKUP(A14,'2022_PAPI_Indicators'!A9:AN189,39,FALSE) -> 0.50463635 | AP14: =VLOOKUP(A14,'2022_PAPI_Indicators'!A9:AO189,40,FALSE) -> 0.30819854 | AQ14: =VLOOKUP(A14,'2022_PAPI_Indicators'!A9:AP189,41,FALSE) -> 0.28203365 | AR14: =VLOOKUP(A14,'2022_PAPI_Indicators'!A9:AQ189,42,FALSE) -> 0.32956079 | AS14: =VLOOKUP(A14,'2022_PAPI_Indicators'!A9:AR189,43,FALSE) -> 0.41997656 | AT14: =VLOOKUP(A14,'2022_PAPI_Indicators'!A9:AS189,44,FALSE) -> 0.35807675 | AU14: =VLOOKUP(A14,'2022_PAPI_Indicators'!A9:AT189,45,FALSE) -> 0.35513392 | AV14: =VLOOKUP(A14,'2022_PAPI_Indicators'!A9:AU189,46,FALSE) -> 0.51081097 | AW14: =VLOOKUP(A14,'2022_PAPI_Indicators'!A9:AV189,47,FALSE) -> 0.34562773 | AX14: =VLOOKUP(A14,'2022_PAPI_Indicators'!A9:AW189,48,FALSE) -> 0.49140191 | AY14: =VLOOKUP(A14,'2022_PAPI_Indicators'!A9:AX189,49,FALSE) -> 0.43852153 | AZ14: =VLOOKUP(A14,'2022_PAPI_Indicators'!A9:AY189,50,FALSE) -> 0.47680795 | BA14: =VLOOKUP(A14,'2022_PAPI_Indicators'!A9:AZ189,51,FALSE) -> 0.35492265 | BB14: =VLOOKUP(A14,'2022_PAPI_Indicators'!A9:BA189,52,FALSE) -> 0.3553507 | BC14: =VLOOKUP(A14,'2022_PAPI_Indicators'!A9:BB189,53,FALSE) -> 0.32874331 | BD14: =VLOOKUP(A14,'2022_PAPI_Indicators'!A9:BC189,54,FALSE) -> 0.28691295 | BE14: =VLOOKUP(A14,'2022_PAPI_Indicators'!A9:BD189,55,FALSE) -> 0.3524434 | BF14: =VLOOKUP(A14,'2022_PAPI_Indicators'!A9:BE189,56,FALSE) -> 0.41717947 | BG14: =VLOOKUP(A14,'2022_PAPI_Indicators'!A9:BF189,57,FALSE) -> 0.28778923 | BH14: =VLOOKUP(A14,'2022_PAPI_Indicators'!A9:BG189,58,FALSE) -> 0.27624071 | BI14: =VLOOKUP(A14,'2022_PAPI_Indicators'!A9:BH189,59,FALSE) -> 0.28387603 | BJ14: =VLOOKUP(A14,'2022_PAPI_Indicators'!A9:BI189,60,FALSE) -> 0.22083662 | BK14: =VLOOKUP(A14,'2022_PAPI_Indicators'!A9:BJ189,61,FALSE) -> 0.37620419 | BL14: =VLOOKUP(A14,'2022_PAPI_Indicators'!A9:BK189,62,FALSE) -> 0.36490226 | BM14: =VLOOKUP(A14,'2022_PAPI_Indicators'!A9:BL189,63,FALSE) -> 0.48420998 | BN14: =VLOOKUP(A14,'2022_PAPI_Indicators'!A9:BM189,64,FALSE) -> 0.39233506
A15: Opportunties for Participation in Elections | B15: 1.2: Cơ hội tham gia | C15: 0.25-2.5 điểm/points | D15: =VLOOKUP(A15,'2022_PAPI_Indicators'!A10:B190,2, FALSE) -> 1.6858891 | E15: =VLOOKUP(A15,'2022_PAPI_Indicators'!A10:C190,3,FALSE) -> 1.6748725 | F15: =VLOOKUP(A15,'2022_PAPI_Indicators'!A10:D190,4,FALSE) -> 1.4802313 | G15: =VLOOKUP(A15,'2022_PAPI_Indicators'!A10:E190,5,FALSE) -> 1.7379497 | H15: =VLOOKUP(A15,'2022_PAPI_Indicators'!A10:F190,6,FALSE) -> 1.4591824 | I15: =VLOOKUP(A15,'2022_PAPI_Indicators'!A10:G190,7,FALSE) -> 1.5429832 | J15: =VLOOKUP(A15,'2022_PAPI_Indicators'!A10:H190,8,FALSE) -> 1.4482298 | K15: =VLOOKUP(A15,'2022_PAPI_Indicators'!A10:I190,9,FALSE) -> 1.6255341 | L15: =VLOOKUP(A15,'2022_PAPI_Indicators'!A10:J190,10,FALSE) -> 1.491834 | M15: =VLOOKUP(A15,'2022_PAPI_Indicators'!A10:K190,11,FALSE) -> 1.4510061 | N15: =VLOOKUP(A15,'2022_PAPI_Indicators'!A10:L190,12,FALSE) -> 1.6131388 | O15: =VLOOKUP(A15,'2022_PAPI_Indicators'!A10:M190,13,FALSE) -> 1.646663 | P15: =VLOOKUP(A15,'2022_PAPI_Indicators'!A10:N190,14,FALSE) -> 1.8705709 | Q15: =VLOOKUP(A15,'2022_PAPI_Indicators'!A10:O190,15,FALSE) -> 1.7197329 | R15: =VLOOKUP(A15,'2022_PAPI_Indicators'!A10:P190,16,FALSE) -> 0 | S15: =VLOOKUP(A15,'2022_PAPI_Indicators'!A10:R190,17,FALSE) -> 1.6887547 | T15: =VLOOKUP(A15,'2022_PAPI_Indicators'!A10:S190,18,FALSE) -> 1.5847507 | U15: =VLOOKUP(A15,'2022_PAPI_Indicators'!A10:T190,19,FALSE) -> 1.6553538 | V15: =VLOOKUP(A15,'2022_PAPI_Indicators'!A10:U190,20,FALSE) -> 1.5862805 | W15: =VLOOKUP(A15,'2022_PAPI_Indicators'!A10:V190,21,FALSE) -> 1.6587526 | X15: =VLOOKUP(A15,'2022_PAPI_Indicators'!A10:W190,22,FALSE) -> 1.7242151 | Y15: =VLOOKUP(A15,'2022_PAPI_Indicators'!A10:X190,23,FALSE) -> 1.6582761 | Z15: =VLOOKUP(A15,'2022_PAPI_Indicators'!A10:Y190,24,FALSE) -> 1.3520112 | AA15: =VLOOKUP(A15,'2022_PAPI_Indicators'!A10:Z190,25,FALSE) -> 1.8323445 | AB15: =VLOOKUP(A15,'2022_PAPI_Indicators'!A10:AA190,26,FALSE) -> 1.5946207 | AC15: =VLOOKUP(A15,'2022_PAPI_Indicators'!A10:AB190,27,FALSE) -> 1.8365793 | AD15: =VLOOKUP(A15,'2022_PAPI_Indicators'!A10:AC190,28,FALSE) -> 1.6218816 | AE15: =VLOOKUP(A15,'2022_PAPI_Indicators'!A10:AD190,29,FALSE) -> 1.555583 | AF15: =VLOOKUP(A15,'2022_PAPI_Indicators'!A10:AE190,30,FALSE) -> 1.4092005 | AG15: =VLOOKUP(A15,'2022_PAPI_Indicators'!A10:AF190,31,FALSE) -> 1.619221 | AH15: =VLOOKUP(A15,'2022_PAPI_Indicators'!A10:AG190,32,FALSE) -> 1.7578712 | AI15: =VLOOKUP(A15,'2022_PAPI_Indicators'!A10:AH190,33,FALSE) -> 1.2245728 | AJ15: =VLOOKUP(A15,'2022_PAPI_Indicators'!A10:AI190,34,FALSE) -> 1.4838569 | AK15: =VLOOKUP(A15,'2022_PAPI_Indicators'!A10:AJ190,35,FALSE) -> 1.3661906 | AL15: =VLOOKUP(A15,'2022_PAPI_Indicators'!A10:AK190,36,FALSE) -> 1.2528048 | AM15: =VLOOKUP(A15,'2022_PAPI_Indicators'!A10:AL190,37,FALSE) -> 1.2769681 | AN15: =VLOOKUP(A15,'2022_PAPI_Indicators'!A10:AM190,38,FALSE) -> 1.2934741 | AO15: =VLOOKUP(A15,'2022_PAPI_Indicators'!A10:AN190,39,FALSE) -> 1.5693754 | AP15: =VLOOKUP(A15,'2022_PAPI_Indicators'!A10:AO190,40,FALSE) -> 1.4772862 | AQ15: =VLOOKUP(A15,'2022_PAPI_Indicators'!A10:AP190,41,FALSE) -> 1.2758796 | AR15: =VLOOKUP(A15,'2022_PAPI_Indicators'!A10:AQ190,42,FALSE) -> 1.3779695 | AS15: =VLOOKUP(A15,'2022_PAPI_Indicators'!A10:AR190,43,FALSE) -> 1.2940778 | AT15: =VLOOKUP(A15,'2022_PAPI_Indicators'!A10:AS190,44,FALSE) -> 1.3254147 | AU15: =VLOOKUP(A15,'2022_PAPI_Indicators'!A10:AT190,45,FALSE) -> 1.6073618 | AV15: =VLOOKUP(A15,'2022_PAPI_Indicators'!A10:AU190,46,FALSE) -> 1.4291593 | AW15: =VLOOKUP(A15,'2022_PAPI_Indicators'!A10:AV190,47,FALSE) -> 1.3203039 | AX15: =VLOOKUP(A15,'2022_PAPI_Indicators'!A10:AW190,48,FALSE) -> 1.6840084 | AY15: =VLOOKUP(A15,'2022_PAPI_Indicators'!A10:AX190,49,FALSE) -> 1.2321833 | AZ15: =VLOOKUP(A15,'2022_PAPI_Indicators'!A10:AY190,50,FALSE) -> 1.1562206 | BA15: =VLOOKUP(A15,'2022_PAPI_Indicators'!A10:AZ190,51,FALSE) -> 1.1008694 | BB15: =VLOOKUP(A15,'2022_PAPI_Indicators'!A10:BA190,52,FALSE) -> 1.2320647 | BC15: =VLOOKUP(A15,'2022_PAPI_Indicators'!A10:BB190,53,FALSE) -> 1.0187954 | BD15: =VLOOKUP(A15,'2022_PAPI_Indicators'!A10:BC190,54,FALSE) -> 1.2090013 | BE15: =VLOOKUP(A15,'2022_PAPI_Indicators'!A10:BD190,55,FALSE) -> 1.0226616 | BF15: =VLOOKUP(A15,'2022_PAPI_Indicators'!A10:BE190,56,FALSE) -> 1.2073089 | BG15: =VLOOKUP(A15,'2022_PAPI_Indicators'!A10:BF190,57,FALSE) -> 1.0155619 | BH15: =VLOOKUP(A15,'2022_PAPI_Indicators'!A10:BG190,58,FALSE) -> 1.1896967 | BI15: =VLOOKUP(A15,'2022_PAPI_Indicators'!A10:BH190,59,FALSE) -> 1.030609 | BJ15: =VLOOKUP(A15,'2022_PAPI_Indicators'!A10:BI190,60,FALSE) -> 0.93527645 | BK15: =VLOOKUP(A15,'2022_PAPI_Indicators'!A10:BJ190,61,FALSE) -> 1.080825 | BL15: =VLOOKUP(A15,'2022_PAPI_Indicators'!A10:BK190,62,FALSE) -> 1.0260128 | BM15: =VLOOKUP(A15,'2022_PAPI_Indicators'!A10:BL190,63,FALSE) -> 1.3811184 | BN15: =VLOOKUP(A15,'2022_PAPI_Indicators'!A10:BM190,64,FALSE) -> 1.0920784
A16: Participated in Formal Associations | B16: Tham gia vào các tổ chức chính trị, chính trị-xã hội, đoàn thể (%) | C16: 0%-100% | D16: =VLOOKUP(A16,'2022_PAPI_Indicators'!A11:B191,2,) -> 0.52566236 | E16: =VLOOKUP(A16,'2022_PAPI_Indicators'!A11:C191,3,FALSE) -> 0.48129657 | F16: =VLOOKUP(A16,'2022_PAPI_Indicators'!A11:D191,4,FALSE) -> 0.45272407 | G16: =VLOOKUP(A16,'2022_PAPI_Indicators'!A11:E191,5,FALSE) -> 0.51974356 | H16: =VLOOKUP(A16,'2022_PAPI_Indicators'!A11:F191,6,FALSE) -> 0.68701881 | I16: =VLOOKUP(A16,'2022_PAPI_Indicators'!A11:G191,7,FALSE) -> 0.50485867 | J16: =VLOOKUP(A16,'2022_PAPI_Indicators'!A11:H191,8,FALSE) -> 0.56712836 | K16: =VLOOKUP(A16,'2022_PAPI_Indicators'!A11:I191,9,FALSE) -> 0.46878967 | L16: =VLOOKUP(A16,'2022_PAPI_Indicators'!A11:J191,10,FALSE) -> 0.50693107 | M16: =VLOOKUP(A16,'2022_PAPI_Indicators'!A11:K191,11,FALSE) -> 0.69093895 | N16: =VLOOKUP(A16,'2022_PAPI_Indicators'!A11:L191,12,FALSE) -> 0.55138361 | O16: =VLOOKUP(A16,'2022_PAPI_Indicators'!A11:M191,13,FALSE) -> 0.65295714 | P16: =VLOOKUP(A16,'2022_PAPI_Indicators'!A11:N191,14,FALSE) -> 0.58380204 | Q16: =VLOOKUP(A16,'2022_PAPI_Indicators'!A11:O191,15,FALSE) -> 0.67091429 | R16: =VLOOKUP(A16,'2022_PAPI_Indicators'!A11:P191,16,FALSE) -> 0 | S16: =VLOOKUP(A16,'2022_PAPI_Indicators'!A11:R191,17,FALSE) -> 0.59723258 | T16: =VLOOKUP(A16,'2022_PAPI_Indicators'!A11:S191,18,FALSE) -> 0.56564224 | U16: =VLOOKUP(A16,'2022_PAPI_Indicators'!A11:T191,19,FALSE) -> 0.53478014 | V16: =VLOOKUP(A16,'2022_PAPI_Indicators'!A11:U191,20,FALSE) -> 0.55125588 | W16: =VLOOKUP(A16,'2022_PAPI_Indicators'!A11:V191,21,FALSE) -> 0.51898491 | X16: =VLOOKUP(A16,'2022_PAPI_Indicators'!A11:W191,22,FALSE) -> 0.66233784 | Y16: =VLOOKUP(A16,'2022_PAPI_Indicators'!A11:X191,23,FALSE) -> 0.69022465 | Z16: =VLOOKUP(A16,'2022_PAPI_Indicators'!A11:Y191,24,FALSE) -> 0.45192742 | AA16: =VLOOKUP(A16,'2022_PAPI_Indicators'!A11:Z191,25,FALSE) -> 0.65854812 | AB16: =VLOOKUP(A16,'2022_PAPI_Indicators'!A11:AA191,26,FALSE) -> 0.5508616 | AC16: =VLOOKUP(A16,'2022_PAPI_Indicators'!A11:AB191,27,FALSE) -> 0.61385465 | AD16: =VLOOKUP(A16,'2022_PAPI_Indicators'!A11:AC191,28,FALSE) -> 0.67189449 | AE16: =VLOOKUP(A16,'2022_PAPI_Indicators'!A11:AD191,29,FALSE) -> 0.67384642 | AF16: =VLOOKUP(A16,'2022_PAPI_Indicators'!A11:AE191,30,FALSE) -> 0.44953349 | AG16: =VLOOKUP(A16,'2022_PAPI_Indicators'!A11:AF191,31,FALSE) -> 0.54843676 | AH16: =VLOOKUP(A16,'2022_PAPI_Indicators'!A11:AG191,32,FALSE) -> 0.65091664 | AI16: =VLOOKUP(A16,'2022_PAPI_Indicators'!A11:AH191,33,FALSE) -> 0.35081804 | AJ16: =VLOOKUP(A16,'2022_PAPI_Indicators'!A11:AI191,34,FALSE) -> 0.31073239 | AK16: =VLOOKUP(A16,'2022_PAPI_Indicators'!A11:AJ191,35,FALSE) -> 0.39753115 | AL16: =VLOOKUP(A16,'2022_PAPI_Indicators'!A11:AK191,36,FALSE) -> 0.3755984 | AM16: =VLOOKUP(A16,'2022_PAPI_Indicators'!A11:AL191,37,FALSE) -> 0.33180428 | AN16: =VLOOKUP(A16,'2022_PAPI_Indicators'!A11:AM191,38,FALSE) -> 0.48141867 | AO16: =VLOOKUP(A16,'2022_PAPI_Indicators'!A11:AN191,39,FALSE) -> 0.40470031 | AP16: =VLOOKUP(A16,'2022_PAPI_Indicators'!A11:AO191,40,FALSE) -> 0.38609645 | AQ16: =VLOOKUP(A16,'2022_PAPI_Indicators'!A11:AP191,41,FALSE) -> 0.38821992 | AR16: =VLOOKUP(A16,'2022_PAPI_Indicators'!A11:AQ191,42,FALSE) -> 0.54527056 | AS16: =VLOOKUP(A16,'2022_PAPI_Indicators'!A11:AR191,43,FALSE) -> 0.38720459 | AT16: =VLOOKUP(A16,'2022_PAPI_Indicators'!A11:AS191,44,FALSE) -> 0.42482138 | AU16: =VLOOKUP(A16,'2022_PAPI_Indicators'!A11:AT191,45,FALSE) -> 0.42008302 | AV16: =VLOOKUP(A16,'2022_PAPI_Indicators'!A11:AU191,46,FALSE) -> 0.47275978 | AW16: =VLOOKUP(A16,'2022_PAPI_Indicators'!A11:AV191,47,FALSE) -> 0.23596448 | AX16: =VLOOKUP(A16,'2022_PAPI_Indicators'!A11:AW191,48,FALSE) -> 0.34234366 | AY16: =VLOOKUP(A16,'2022_PAPI_Indicators'!A11:AX191,49,FALSE) -> 0.31424996 | AZ16: =VLOOKUP(A16,'2022_PAPI_Indicators'!A11:AY191,50,FALSE) -> 0.30161712 | BA16: =VLOOKUP(A16,'2022_PAPI_Indicators'!A11:AZ191,51,FALSE) -> 0.24093547 | BB16: =VLOOKUP(A16,'2022_PAPI_Indicators'!A11:BA191,52,FALSE) -> 0.17811303 | BC16: =VLOOKUP(A16,'2022_PAPI_Indicators'!A11:BB191,53,FALSE) -> 0.17473339 | BD16: =VLOOKUP(A16,'2022_PAPI_Indicators'!A11:BC191,54,FALSE) -> 0.37331843 | BE16: =VLOOKUP(A16,'2022_PAPI_Indicators'!A11:BD191,55,FALSE) -> 0.26923525 | BF16: =VLOOKUP(A16,'2022_PAPI_Indicators'!A11:BE191,56,FALSE) -> 0.38646275 | BG16: =VLOOKUP(A16,'2022_PAPI_Indicators'!A11:BF191,57,FALSE) -> 0.29203346 | BH16: =VLOOKUP(A16,'2022_PAPI_Indicators'!A11:BG191,58,FALSE) -> 0.1811879 | BI16: =VLOOKUP(A16,'2022_PAPI_Indicators'!A11:BH191,59,FALSE) -> 0.25242013 | BJ16: =VLOOKUP(A16,'2022_PAPI_Indicators'!A11:BI191,60,FALSE) -> 0.15665367 | BK16: =VLOOKUP(A16,'2022_PAPI_Indicators'!A11:BJ191,61,FALSE) -> 0.27813601 | BL16: =VLOOKUP(A16,'2022_PAPI_Indicators'!A11:BK191,62,FALSE) -> 0.25828972 | BM16: =VLOOKUP(A16,'2022_PAPI_Indicators'!A11:BL191,63,FALSE) -> 0.29723966 | BN16: =VLOOKUP(A16,'2022_PAPI_Indicators'!A11:BM191,64,FALSE) -> 0.39738056
A17: Participated in Informal Associations | B17: Tham gia vào các tổ chức xã hội, hội, nhóm, câu lạc bộ tự lập (%) | C17: 0%-100% | D17: =VLOOKUP(A17,'2022_PAPI_Indicators'!A12:B192,2,) -> 0.21529262 | E17: =VLOOKUP(A17,'2022_PAPI_Indicators'!A12:C192,3,FALSE) -> 0.1416005 | F17: =VLOOKUP(A17,'2022_PAPI_Indicators'!A12:D192,4,FALSE) -> 0.063408643 | G17: =VLOOKUP(A17,'2022_PAPI_Indicators'!A12:E192,5,FALSE) -> 0.16764528 | H17: =VLOOKUP(A17,'2022_PAPI_Indicators'!A12:F192,6,FALSE) -> 0.18536884 | I17: =VLOOKUP(A17,'2022_PAPI_Indicators'!A12:G192,7,FALSE) -> 0.2141833 | J17: =VLOOKUP(A17,'2022_PAPI_Indicators'!A12:H192,8,FALSE) -> 0.14865138 | K17: =VLOOKUP(A17,'2022_PAPI_Indicators'!A12:I192,9,FALSE) -> 0.10830277 | L17: =VLOOKUP(A17,'2022_PAPI_Indicators'!A12:J192,10,FALSE) -> 0.11076121 | M17: =VLOOKUP(A17,'2022_PAPI_Indicators'!A12:K192,11,FALSE) -> 0.20469046 | N17: =VLOOKUP(A17,'2022_PAPI_Indicators'!A12:L192,12,FALSE) -> 0.14050679 | O17: =VLOOKUP(A17,'2022_PAPI_Indicators'!A12:M192,13,FALSE) -> 0.17394799 | P17: =VLOOKUP(A17,'2022_PAPI_Indicators'!A12:N192,14,FALSE) -> 0.15009549 | Q17: =VLOOKUP(A17,'2022_PAPI_Indicators'!A12:O192,15,FALSE) -> 0.28384075 | R17: =VLOOKUP(A17,'2022_PAPI_Indicators'!A12:P192,16,FALSE) -> 0 | S17: =VLOOKUP(A17,'2022_PAPI_Indicators'!A12:R192,17,FALSE) -> 0.22493558 | T17: =VLOOKUP(A17,'2022_PAPI_Indicators'!A12:S192,18,FALSE) -> 0.17097297 | U17: =VLOOKUP(A17,'2022_PAPI_Indicators'!A12:T192,19,FALSE) -> 0.30540964 | V17: =VLOOKUP(A17,'2022_PAPI_Indicators'!A12:U192,20,FALSE) -> 0.15984136 | W17: =VLOOKUP(A17,'2022_PAPI_Indicators'!A12:V192,21,FALSE) -> 0.1269387 | X17: =VLOOKUP(A17,'2022_PAPI_Indicators'!A12:W192,22,FALSE) -> 0.22197172 | Y17: =VLOOKUP(A17,'2022_PAPI_Indicators'!A12:X192,23,FALSE) -> 0.10595744 | Z17: =VLOOKUP(A17,'2022_PAPI_Indicators'!A12:Y192,24,FALSE) -> 0.13277367 | AA17: =VLOOKUP(A17,'2022_PAPI_Indicators'!A12:Z192,25,FALSE) -> 0.24444713 | AB17: =VLOOKUP(A17,'2022_PAPI_Indicators'!A12:AA192,26,FALSE) -> 0.21257718 | AC17: =VLOOKUP(A17,'2022_PAPI_Indicators'!A12:AB192,27,FALSE) -> 0.23494346 | AD17: =VLOOKUP(A17,'2022_PAPI_Indicators'!A12:AC192,28,FALSE) -> 0.23169768 | AE17: =VLOOKUP(A17,'2022_PAPI_Indicators'!A12:AD192,29,FALSE) -> 0.23831788 | AF17: =VLOOKUP(A17,'2022_PAPI_Indicators'!A12:AE192,30,FALSE) -> 0.22905476 | AG17: =VLOOKUP(A17,'2022_PAPI_Indicators'!A12:AF192,31,FALSE) -> 0.125 | AH17: =VLOOKUP(A17,'2022_PAPI_Indicators'!A12:AG192,32,FALSE) -> 0.17572054 | AI17: =VLOOKUP(A17,'2022_PAPI_Indicators'!A12:AH192,33,FALSE) -> 0.10579033 | AJ17: =VLOOKUP(A17,'2022_PAPI_Indicators'!A12:AI192,34,FALSE) -> 0.10249674 | AK17: =VLOOKUP(A17,'2022_PAPI_Indicators'!A12:AJ192,35,FALSE) -> 0.094414383 | AL17: =VLOOKUP(A17,'2022_PAPI_Indicators'!A12:AK192,36,FALSE) -> 0.068271555 | AM17: =VLOOKUP(A17,'2022_PAPI_Indicators'!A12:AL192,37,FALSE) -> 0.125 | AN17: =VLOOKUP(A17,'2022_PAPI_Indicators'!A12:AM192,38,FALSE) -> 0.085443251 | AO17: =VLOOKUP(A17,'2022_PAPI_Indicators'!A12:AN192,39,FALSE) -> 0.092847072 | AP17: =VLOOKUP(A17,'2022_PAPI_Indicators'!A12:AO192,40,FALSE) -> 0.080389269 | AQ17: =VLOOKUP(A17,'2022_PAPI_Indicators'!A12:AP192,41,FALSE) -> 0.183053 | AR17: =VLOOKUP(A17,'2022_PAPI_Indicators'!A12:AQ192,42,FALSE) -> 0.14197646 | AS17: =VLOOKUP(A17,'2022_PAPI_Indicators'!A12:AR192,43,FALSE) -> 0.047440119 | AT17: =VLOOKUP(A17,'2022_PAPI_Indicators'!A12:AS192,44,FALSE) -> 0.12188566 | AU17: =VLOOKUP(A17,'2022_PAPI_Indicators'!A12:AT192,45,FALSE) -> 0.11246698 | AV17: =VLOOKUP(A17,'2022_PAPI_Indicators'!A12:AU192,46,FALSE) -> 0.10320074 | AW17: =VLOOKUP(A17,'2022_PAPI_Indicators'!A12:AV192,47,FALSE) -> 0.046489753 | AX17: =VLOOKUP(A17,'2022_PAPI_Indicators'!A12:AW192,48,FALSE) -> 0.11278021 | AY17: =VLOOKUP(A17,'2022_PAPI_Indicators'!A12:AX192,49,FALSE) -> 0.090927698 | AZ17: =VLOOKUP(A17,'2022_PAPI_Indicators'!A12:AY192,50,FALSE) -> 0.10356939 | BA17: =VLOOKUP(A17,'2022_PAPI_Indicators'!A12:AZ192,51,FALSE) -> 0.066570714 | BB17: =VLOOKUP(A17,'2022_PAPI_Indicators'!A12:BA192,52,FALSE) -> 0.050726984 | BC17: =VLOOKUP(A17,'2022_PAPI_Indicators'!A12:BB192,53,FALSE) -> 0.074875973 | BD17: =VLOOKUP(A17,'2022_PAPI_Indicators'!A12:BC192,54,FALSE) -> 0.12232926 | BE17: =VLOOKUP(A17,'2022_PAPI_Indicators'!A12:BD192,55,FALSE) -> 0.10454214 | BF17: =VLOOKUP(A17,'2022_PAPI_Indicators'!A12:BE192,56,FALSE) -> 0.10268801 | BG17: =VLOOKUP(A17,'2022_PAPI_Indicators'!A12:BF192,57,FALSE) -> 0.13069038 | BH17: =VLOOKUP(A17,'2022_PAPI_Indicators'!A12:BG192,58,FALSE) -> 0.12772396 | BI17: =VLOOKUP(A17,'2022_PAPI_Indicators'!A12:BH192,59,FALSE) -> 0.075922273 | BJ17: =VLOOKUP(A17,'2022_PAPI_Indicators'!A12:BI192,60,FALSE) -> 0.18827076 | BK17: =VLOOKUP(A17,'2022_PAPI_Indicators'!A12:BJ192,61,FALSE) -> 0.13504754 | BL17: =VLOOKUP(A17,'2022_PAPI_Indicators'!A12:BK192,62,FALSE) -> 0.10149556 | BM17: =VLOOKUP(A17,'2022_PAPI_Indicators'!A12:BL192,63,FALSE) -> 0.12244929 | BN17: =VLOOKUP(A17,'2022_PAPI_Indicators'!A12:BM192,64,FALSE) -> 0.1004942
A18: Voted in Last Communce People's Council Election | B18: Tỷ lệ người trả lời đã tham gia bầu cử đại biểu Hội đồng Nhân dân lần gần đây nhất (%) | C18: 0%-100% | D18: =VLOOKUP(A18,'2022_PAPI_Indicators'!A13:B193,2,) -> 0.74945217 | E18: =VLOOKUP(A18,'2022_PAPI_Indicators'!A13:C193,3,FALSE) -> 0.78490156 | F18: =VLOOKUP(A18,'2022_PAPI_Indicators'!A13:D193,4,FALSE) -> 0.70206487 | G18: =VLOOKUP(A18,'2022_PAPI_Indicators'!A13:E193,5,FALSE) -> 0.7780605 | H18: =VLOOKUP(A18,'2022_PAPI_Indicators'!A13:F193,6,FALSE) -> 0.57972807 | I18: =VLOOKUP(A18,'2022_PAPI_Indicators'!A13:G193,7,FALSE) -> 0.71120441 | J18: =VLOOKUP(A18,'2022_PAPI_Indicators'!A13:H193,8,FALSE) -> 0.57454067 | K18: =VLOOKUP(A18,'2022_PAPI_Indicators'!A13:I193,9,FALSE) -> 0.77319324 | L18: =VLOOKUP(A18,'2022_PAPI_Indicators'!A13:J193,10,FALSE) -> 0.75557578 | M18: =VLOOKUP(A18,'2022_PAPI_Indicators'!A13:K193,11,FALSE) -> 0.54948944 | N18: =VLOOKUP(A18,'2022_PAPI_Indicators'!A13:L193,12,FALSE) -> 0.75360602 | O18: =VLOOKUP(A18,'2022_PAPI_Indicators'!A13:M193,13,FALSE) -> 0.72394592 | P18: =VLOOKUP(A18,'2022_PAPI_Indicators'!A13:N193,14,FALSE) -> 0.82326102 | Q18: =VLOOKUP(A18,'2022_PAPI_Indicators'!A13:O193,15,FALSE) -> 0.77582473 | R18: =VLOOKUP(A18,'2022_PAPI_Indicators'!A13:P193,16,FALSE) -> 0 | S18: =VLOOKUP(A18,'2022_PAPI_Indicators'!A13:R193,17,FALSE) -> 0.71761078 | T18: =VLOOKUP(A18,'2022_PAPI_Indicators'!A13:S193,18,FALSE) -> 0.79972136 | U18: =VLOOKUP(A18,'2022_PAPI_Indicators'!A13:T193,19,FALSE) -> 0.80611944 | V18: =VLOOKUP(A18,'2022_PAPI_Indicators'!A13:U193,20,FALSE) -> 0.68382573 | W18: =VLOOKUP(A18,'2022_PAPI_Indicators'!A13:V193,21,FALSE) -> 0.57827544 | X18: =VLOOKUP(A18,'2022_PAPI_Indicators'!A13:W193,22,FALSE) -> 0.78605717 | Y18: =VLOOKUP(A18,'2022_PAPI_Indicators'!A13:X193,23,FALSE) -> 0.75141448 | Z18: =VLOOKUP(A18,'2022_PAPI_Indicators'!A13:Y193,24,FALSE) -> 0.81099421 | AA18: =VLOOKUP(A18,'2022_PAPI_Indicators'!A13:Z193,25,FALSE) -> 0.7079677 | AB18: =VLOOKUP(A18,'2022_PAPI_Indicators'!A13:AA193,26,FALSE) -> 0.66199976 | AC18: =VLOOKUP(A18,'2022_PAPI_Indicators'!A13:AB193,27,FALSE) -> 0.66692263 | AD18: =VLOOKUP(A18,'2022_PAPI_Indicators'!A13:AC193,28,FALSE) -> 0.80546135 | AE18: =VLOOKUP(A18,'2022_PAPI_Indicators'!A13:AD193,29,FALSE) -> 0.79755926 | AF18: =VLOOKUP(A18,'2022_PAPI_Indicators'!A13:AE193,30,FALSE) -> 0.58251774 | AG18: =VLOOKUP(A18,'2022_PAPI_Indicators'!A13:AF193,31,FALSE) -> 0.72376513 | AH18: =VLOOKUP(A18,'2022_PAPI_Indicators'!A13:AG193,32,FALSE) -> 0.62310815 | AI18: =VLOOKUP(A18,'2022_PAPI_Indicators'!A13:AH193,33,FALSE) -> 0.60801739 | AJ18: =VLOOKUP(A18,'2022_PAPI_Indicators'!A13:AI193,34,FALSE) -> 0.63452303 | AK18: =VLOOKUP(A18,'2022_PAPI_Indicators'!A13:AJ193,35,FALSE) -> 0.57710814 | AL18: =VLOOKUP(A18,'2022_PAPI_Indicators'!A13:AK193,36,FALSE) -> 0.72496796 | AM18: =VLOOKUP(A18,'2022_PAPI_Indicators'!A13:AL193,37,FALSE) -> 0.67858714 | AN18: =VLOOKUP(A18,'2022_PAPI_Indicators'!A13:AM193,38,FALSE) -> 0.57040071 | AO18: =VLOOKUP(A18,'2022_PAPI_Indicators'!A13:AN193,39,FALSE) -> 0.60393029 | AP18: =VLOOKUP(A18,'2022_PAPI_Indicators'!A13:AO193,40,FALSE) -> 0.61632484 | AQ18: =VLOOKUP(A18,'2022_PAPI_Indicators'!A13:AP193,41,FALSE) -> 0.60337746 | AR18: =VLOOKUP(A18,'2022_PAPI_Indicators'!A13:AQ193,42,FALSE) -> 0.71357143 | AS18: =VLOOKUP(A18,'2022_PAPI_Indicators'!A13:AR193,43,FALSE) -> 0.679061 | AT18: =VLOOKUP(A18,'2022_PAPI_Indicators'!A13:AS193,44,FALSE) -> 0.66793531 | AU18: =VLOOKUP(A18,'2022_PAPI_Indicators'!A13:AT193,45,FALSE) -> 0.77918816 | AV18: =VLOOKUP(A18,'2022_PAPI_Indicators'!A13:AU193,46,FALSE) -> 0.57612455 | AW18: =VLOOKUP(A18,'2022_PAPI_Indicators'!A13:AV193,47,FALSE) -> 0.5179643 | AX18: =VLOOKUP(A18,'2022_PAPI_Indicators'!A13:AW193,48,FALSE) -> 0.5167073 | AY18: =VLOOKUP(A18,'2022_PAPI_Indicators'!A13:AX193,49,FALSE) -> 0.64657575 | AZ18: =VLOOKUP(A18,'2022_PAPI_Indicators'!A13:AY193,50,FALSE) -> 0.55870593 | BA18: =VLOOKUP(A18,'2022_PAPI_Indicators'!A13:AZ193,51,FALSE) -> 0.59736276 | BB18: =VLOOKUP(A18,'2022_PAPI_Indicators'!A13:BA193,52,FALSE) -> 0.5052675 | BC18: =VLOOKUP(A18,'2022_PAPI_Indicators'!A13:BB193,53,FALSE) -> 0.56855392 | BD18: =VLOOKUP(A18,'2022_PAPI_Indicators'!A13:BC193,54,FALSE) -> 0.48033282 | BE18: =VLOOKUP(A18,'2022_PAPI_Indicators'!A13:BD193,55,FALSE) -> 0.56879324 | BF18: =VLOOKUP(A18,'2022_PAPI_Indicators'!A13:BE193,56,FALSE) -> 0.47233474 | BG18: =VLOOKUP(A18,'2022_PAPI_Indicators'!A13:BF193,57,FALSE) -> 0.42368892 | BH18: =VLOOKUP(A18,'2022_PAPI_Indicators'!A13:BG193,58,FALSE) -> 0.53832972 | BI18: =VLOOKUP(A18,'2022_PAPI_Indicators'!A13:BH193,59,FALSE) -> 0.47403485 | BJ18: =VLOOKUP(A18,'2022_PAPI_Indicators'!A13:BI193,60,FALSE) -> 0.59213096 | BK18: =VLOOKUP(A18,'2022_PAPI_Indicators'!A13:BJ193,61,FALSE) -> 0.47905722 | BL18: =VLOOKUP(A18,'2022_PAPI_Indicators'!A13:BK193,62,FALSE) -> 0 | BM18: =VLOOKUP(A18,'2022_PAPI_Indicators'!A13:BL193,63,FALSE) -> 0 | BN18: =VLOOKUP(A18,'2022_PAPI_Indicators'!A13:BM193,64,FALSE) -> 0
A19: Voted in Last National Assembly Election | B19: Tỷ lệ người trả lời đã tham gia bầu cử đại biểu Quốc hội lần gần đây nhất (%) | C19: 0%-100% | D19: =VLOOKUP(A19,'2022_PAPI_Indicators'!A14:B194,2,) -> 0.74786282 | E19: =VLOOKUP(A19,'2022_PAPI_Indicators'!A14:C194,3,FALSE) -> 0.81020534 | F19: =VLOOKUP(A19,'2022_PAPI_Indicators'!A14:D194,4,FALSE) -> 0.65154463 | G19: =VLOOKUP(A19,'2022_PAPI_Indicators'!A14:E194,5,FALSE) -> 0.79713488 | H19: =VLOOKUP(A19,'2022_PAPI_Indicators'!A14:F194,6,FALSE) -> 0.64028108 | I19: =VLOOKUP(A19,'2022_PAPI_Indicators'!A14:G194,7,FALSE) -> 0.63832635 | J19: =VLOOKUP(A19,'2022_PAPI_Indicators'!A14:H194,8,FALSE) -> 0.65302241 | K19: =VLOOKUP(A19,'2022_PAPI_Indicators'!A14:I194,9,FALSE) -> 0.68732178 | L19: =VLOOKUP(A19,'2022_PAPI_Indicators'!A14:J194,10,FALSE) -> 0.5729453 | M19: =VLOOKUP(A19,'2022_PAPI_Indicators'!A14:K194,11,FALSE) -> 0.63508314 | N19: =VLOOKUP(A19,'2022_PAPI_Indicators'!A14:L194,12,FALSE) -> 0.7390244 | O19: =VLOOKUP(A19,'2022_PAPI_Indicators'!A14:M194,13,FALSE) -> 0.70200348 | P19: =VLOOKUP(A19,'2022_PAPI_Indicators'!A14:N194,14,FALSE) -> 0.87235683 | Q19: =VLOOKUP(A19,'2022_PAPI_Indicators'!A14:O194,15,FALSE) -> 0.71905935 | R19: =VLOOKUP(A19,'2022_PAPI_Indicators'!A14:P194,16,FALSE) -> 0 | S19: =VLOOKUP(A19,'2022_PAPI_Indicators'!A14:R194,17,FALSE) -> 0.66345316 | T19: =VLOOKUP(A19,'2022_PAPI_Indicators'!A14:S194,18,FALSE) -> 0.6677416 | U19: =VLOOKUP(A19,'2022_PAPI_Indicators'!A14:T194,19,FALSE) -> 0.66360033 | V19: =VLOOKUP(A19,'2022_PAPI_Indicators'!A14:U194,20,FALSE) -> 0.69982827 | W19: =VLOOKUP(A19,'2022_PAPI_Indicators'!A14:V194,21,FALSE) -> 0.63248181 | X19: =VLOOKUP(A19,'2022_PAPI_Indicators'!A14:W194,22,FALSE) -> 0.8169812 | Y19: =VLOOKUP(A19,'2022_PAPI_Indicators'!A14:X194,23,FALSE) -> 0.60431832 | Z19: =VLOOKUP(A19,'2022_PAPI_Indicators'!A14:Y194,24,FALSE) -> 0.78528416 | AA19: =VLOOKUP(A19,'2022_PAPI_Indicators'!A14:Z194,25,FALSE) -> 0.595653 | AB19: =VLOOKUP(A19,'2022_PAPI_Indicators'!A14:AA194,26,FALSE) -> 0.62172562 | AC19: =VLOOKUP(A19,'2022_PAPI_Indicators'!A14:AB194,27,FALSE) -> 0.53379136 | AD19: =VLOOKUP(A19,'2022_PAPI_Indicators'!A14:AC194,28,FALSE) -> 0.6280638 | AE19: =VLOOKUP(A19,'2022_PAPI_Indicators'!A14:AD194,29,FALSE) -> 0.73459566 | AF19: =VLOOKUP(A19,'2022_PAPI_Indicators'!A14:AE194,30,FALSE) -> 0.53900278 | AG19: =VLOOKUP(A19,'2022_PAPI_Indicators'!A14:AF194,31,FALSE) -> 0.64591604 | AH19: =VLOOKUP(A19,'2022_PAPI_Indicators'!A14:AG194,32,FALSE) -> 0.59006464 | AI19: =VLOOKUP(A19,'2022_PAPI_Indicators'!A14:AH194,33,FALSE) -> 0.50648636 | AJ19: =VLOOKUP(A19,'2022_PAPI_Indicators'!A14:AI194,34,FALSE) -> 0.52722281 | AK19: =VLOOKUP(A19,'2022_PAPI_Indicators'!A14:AJ194,35,FALSE) -> 0.5925349 | AL19: =VLOOKUP(A19,'2022_PAPI_Indicators'!A14:AK194,36,FALSE) -> 0.72001624 | AM19: =VLOOKUP(A19,'2022_PAPI_Indicators'!A14:AL194,37,FALSE) -> 0.64033097 | AN19: =VLOOKUP(A19,'2022_PAPI_Indicators'!A14:AM194,38,FALSE) -> 0.507801 | AO19: =VLOOKUP(A19,'2022_PAPI_Indicators'!A14:AN194,39,FALSE) -> 0.58055681 | AP19: =VLOOKUP(A19,'2022_PAPI_Indicators'!A14:AO194,40,FALSE) -> 0.59338021 | AQ19: =VLOOKUP(A19,'2022_PAPI_Indicators'!A14:AP194,41,FALSE) -> 0.59001821 | AR19: =VLOOKUP(A19,'2022_PAPI_Indicators'!A14:AQ194,42,FALSE) -> 0.77508092 | AS19: =VLOOKUP(A19,'2022_PAPI_Indicators'!A14:AR194,43,FALSE) -> 0.60980207 | AT19: =VLOOKUP(A19,'2022_PAPI_Indicators'!A14:AS194,44,FALSE) -> 0.60837555 | AU19: =VLOOKUP(A19,'2022_PAPI_Indicators'!A14:AT194,45,FALSE) -> 0.79589576 | AV19: =VLOOKUP(A19,'2022_PAPI_Indicators'!A14:AU194,46,FALSE) -> 0.58272934 | AW19: =VLOOKUP(A19,'2022_PAPI_Indicators'!A14:AV194,47,FALSE) -> 0.51297748 | AX19: =VLOOKUP(A19,'2022_PAPI_Indicators'!A14:AW194,48,FALSE) -> 0.56269956 | AY19: =VLOOKUP(A19,'2022_PAPI_Indicators'!A14:AX194,49,FALSE) -> 0.58700371 | AZ19: =VLOOKUP(A19,'2022_PAPI_Indicators'!A14:AY194,50,FALSE) -> 0.44138122 | BA19: =VLOOKUP(A19,'2022_PAPI_Indicators'!A14:AZ194,51,FALSE) -> 0.49736574 | BB19: =VLOOKUP(A19,'2022_PAPI_Indicators'!A14:BA194,52,FALSE) -> 0.41325012 | BC19: =VLOOKUP(A19,'2022_PAPI_Indicators'!A14:BB194,53,FALSE) -> 0.47878551 | BD19: =VLOOKUP(A19,'2022_PAPI_Indicators'!A14:BC194,54,FALSE) -> 0.49789798 | BE19: =VLOOKUP(A19,'2022_PAPI_Indicators'!A14:BD194,55,FALSE) -> 0.59215063 | BF19: =VLOOKUP(A19,'2022_PAPI_Indicators'!A14:BE194,56,FALSE) -> 0.48060468 | BG19: =VLOOKUP(A19,'2022_PAPI_Indicators'!A14:BF194,57,FALSE) -> 0.40239909 | BH19: =VLOOKUP(A19,'2022_PAPI_Indicators'!A14:BG194,58,FALSE) -> 0.45561001 | BI19: =VLOOKUP(A19,'2022_PAPI_Indicators'!A14:BH194,59,FALSE) -> 0.55975407 | BJ19: =VLOOKUP(A19,'2022_PAPI_Indicators'!A14:BI194,60,FALSE) -> 0.65752059 | BK19: =VLOOKUP(A19,'2022_PAPI_Indicators'!A14:BJ194,61,FALSE) -> 0.49570414 | BL19: =VLOOKUP(A19,'2022_PAPI_Indicators'!A14:BK194,62,FALSE) -> 0 | BM19: =VLOOKUP(A19,'2022_PAPI_Indicators'!A14:BL194,63,FALSE) -> 0 | BN19: =VLOOKUP(A19,'2022_PAPI_Indicators'!A14:BM194,64,FALSE) -> 0
